Workbook

Sheet Inputs (2)
B1: Work Order | C1: Product | D1: LL | E1: Category | F1: Qtr | G1: Qty | H1: Completed | I1: Pending | J1: Feb 2nd Week | K1: Feb 3rd Week | L1: Feb 4th Week | M1: Mar 1st Week | N1: Mar 2nd Week | O1: Mar 3rd Weeek | P1: Mar 4th Week | Q1: Stock (WH) | R1: Stock (At OEM) | S1: Confirmed Prod'n | T1: Apr 1st week | U1: Remarks
A2: 1 | B2: BN-SO-2526-0005 | C2: Solaria 4B | E2: Burner | F2: JAS | I2: 0 | Q2: 0 | R2: 0 | S2: =SUM(J2:P2) -> 0
A3: 2 | B3: BN-SO-2526-0002 | C3: Zyra 4 Burner | E3: Burner | F3: JAS | G3: 290 | H3: 260 | I3: =G3-H3 -> 30 | J3: 25 | Q3: 115 | R3: 0 | S3: =SUM(J3:P3) -> 25 | U3: 5 to be shortclosed
A4: 3 | B4: BN-SO-2526-0049 | C4: Solaria 3B | E4: Burner | F4: OND | G4: 350 | H4: =98+85 -> 183 | I4: =G4-H4 -> 167 | J4: 100 | K4: 67 | Q4: 0 | R4: 0 | S4: =SUM(J4:P4) -> 167
A5: 4 | B5: BN-SO-2526-0026 | C5: Arista 60 | D5: 60 | E5: Chimney | F5: OND | G5: 0 | H5: 0 | I5: =G5-H5 -> 0 | P5: 200 | Q5: 0 | R5: 0 | S5: =SUM(J5:P5) -> 200
A6: 5 | B6: BN-SO-2526-0026 | C6: Arista 90 | D6: 60 | E6: Chimney | F6: OND | G6: 0 | H6: 0 | I6: =G6-H6 -> 0 | P6: 200 | Q6: 0 | R6: 0 | S6: =SUM(J6:P6) -> 200
A7: 6 | B7: BN-SO-2526-0023 | C7: Asteria 60 | D7: 60 | E7: Chimney | F7: OND | G7: 600 | H7: 600 | I7: =G7-H7 -> 0 | Q7: 0 | R7: 0 | S7: =SUM(J7:P7) -> 0
A8: 7 | B8: BN-SO-2526-0023 | C8: Asteria 90 | D8: 60 | E8: Chimney | F8: OND | G8: 550 | H8: 550 | I8: =G8-H8 -> 0 | Q8: 0 | R8: 0 | S8: =SUM(J8:P8) -> 0
A9: 8 | B9: BN-SO-2526-0028 | C9: Cube | D9: 75 | E9: Chimney | F9: OND | G9: 4000 | H9: 4000 | I9: =G9-H9 -> 0 | Q9: 0 | R9: 0 | S9: =SUM(J9:P9) -> 0
A10: 9 | B10: BN-SO-2526-0024 | C10: Elara 60 | D10: 60 | E10: Chimney | F10: OND | G10: 0 | H10: 0 | I10: =G10-H10 -> 0 | P10: 0 | Q10: 0 | R10: 0 | S10: =SUM(J10:P10) -> 0 | T10: 250
A11: 10 | B11: BN-SO-2526-0024 | C11: Elara 90 | D11: 60 | E11: Chimney | F11: OND | G11: 0 | H11: 0 | I11: =G11-H11 -> 0 | P11: 0 | Q11: 0 | R11: 0 | S11: =SUM(J11:P11) -> 0 | T11: 250
A12: 11 | B12: BN-SO-2526-0025 | C12: Eris 60 | D12: 60 | E12: Chimney | F12: OND | G12: 0 | H12: 0 | I12: =G12-H12 -> 0 | Q12: 0 | R12: 0 | S12: =SUM(J12:P12) -> 0
A13: 12 | B13: BN-SO-2526-0025 | C13: Eris 90 | D13: 60 | E13: Chimney | F13: OND | G13: 0 | H13: 0 | I13: =G13-H13 -> 0 | Q13: 0 | R13: 0 | S13: =SUM(J13:P13) -> 0
A14: 13 | B14: BN-SO-2526-0022 | C14: Orion | D14: 70 | E14: Chimney | F14: OND | G14: 324 | H14: 324 | I14: =G14-H14 -> 0 | Q14: 0 | R14: 0 | S14: =SUM(J14:P14) -> 0
A15: 14 | B15: BN-SO-2526-0019 | C15: Dorado 3B | D15: 65 | E15: Burner | F15: OND | G15: 800 | H15: 800 | I15: =G15-H15 -> 0 | Q15: 0 | R15: 0 | S15: =SUM(J15:P15) -> 0
A16: 15 | B16: BN-SO-2526-0019 | C16: Dorado 4B | D16: 65 | E16: Burner | F16: OND | G16: 1600 | H16: 1600 | I16: =G16-H16 -> 0 | Q16: 0 | R16: 0 | S16: =SUM(J16:P16) -> 0
A17: 16 | B17: BN-SO-2526-0020 | C17: Altair 4B | D17: 70 | E17: Burner | F17: OND | G17: 1255 | H17: =977+3+6+48+23+52+62+48+15+18+3 -> 1255 | I17: =G17-H17 -> 0 | J17: 0 | Q17: 0 | R17: 0 | S17: =SUM(J17:P17) -> 0
A18: 17 | B18: BN-SO-2526-0042 | C18: Asteria 60 BLDC | E18: Chimney | F18: OND | G18: 50 | H18: 36 | I18: =G18-H18 -> 14 | J18: 14 | Q18: 0 | R18: 0 | S18: =SUM(J18:P18) -> 14
A19: 18 | B19: BN-SO-2526-0042 | C19: Asteria 90 BLDC | E19: Chimney | F19: OND | G19: 50 | H19: 40 | I19: =G19-H19 -> 10 | J19: 10 | Q19: 0 | R19: 0 | S19: =SUM(J19:P19) -> 10
A20: 19 | B20: BN-SO-2526-0050 | C20: Solaria 4B | E20: Burner | F20: OND | G20: 550 | H20: =185+57 -> 242 | I20: =G20-H20 -> 308 | J20: 200 | K20: 108 | Q20: 0 | R20: 0 | S20: =SUM(J20:P20) -> 308
A21: 20 | B21: BN-SO-2526-0040 | C21: Solaria 3B | E21: Burner | F21: January | G21: 275 | H21: 0 | I21: =G21-H21 -> 275 | M21: 275 | Q21: 0 | R21: 0 | S21: =SUM(J21:P21) -> 275
A22: 21 | B22: BN-SO-2526-0039 | C22: Auriga 4B | E22: Burner | F22: January | G22: 800 | H22: 0 | I22: =G22-H22 -> 800 | J22: 100 | K22: 400 | L22: 300 | Q22: 0 | R22: 0 | S22: =SUM(J22:P22) -> 800
A23: 22 | B23: BN-SO-2526-0041 | C23: Solaria 4B | E23: Burner | F23: January | G23: 400 | H23: 0 | I23: =G23-H23 -> 400 | M23: 400 | Q23: 0 | R23: 0 | S23: =SUM(J23:P23) -> 400
A24: 23 | B24: BN-SO-2526-0029 | C24: Asteria 60 | E24: Chimney | F24: January | G24: 200 | H24: =135+65 -> 200 | I24: =G24-H24 -> 0 | Q24: 0 | R24: 0 | S24: =SUM(J24:P24) -> 0
A25: 24 | B25: BN-SO-2526-0030 | C25: Asteria 90 | E25: Chimney | F25: January | G25: 0 | H25: 0 | I25: =G25-H25 -> 0 | Q25: 0 | R25: 0 | S25: =SUM(J25:P25) -> 0
A26: 25 | B26: BN-SO-2526-0034 | C26: Cube | E26: Chimney | F26: January | G26: 3000 | H26: 0 | I26: =G26-H26 -> 3000 | J26: 500 | K26: 1500 | L26: 1000 | Q26: 0 | R26: 0 | S26: =SUM(J26:P26) -> 3000
A27: 26 | B27: BN-SO-2526-0032 | C27: Eris 60 | E27: Chimney | F27: January | G27: 0 | H27: 0 | I27: =G27-H27 -> 0 | M27: 0 | Q27: 0 | R27: 0 | S27: =SUM(J27:P27) -> 0
A28: 27 | B28: BN-SO-2526-0033 | C28: Eris 90 | E28: Chimney | F28: January | G28: 0 | H28: 0 | I28: =G28-H28 -> 0 | M28: 0 | Q28: 0 | R28: 0 | S28: =SUM(J28:P28) -> 0
A29: 28 | B29: BN-SO-2526-0031 | C29: Orion | E29: Chimney | F29: January | G29: 324 | H29: =54+40+35+35+40+32+40+12+34 -> 322 | I29: =G29-H29 -> 2 | Q29: =4+20+96 -> 120 | R29: 50 | S29: =SUM(J29:P29) -> 0
A30: 29 | B30: BN-SO-2526-0036 | C30: Dorado 3B | E30: Burner | F30: January | G30: 300 | H30: =243 -> 243 | I30: =G30-H30 -> 57 | K30: 57 | Q30: 0 | R30: 0 | S30: =SUM(J30:P30) -> 57
A31: 30 | B31: BN-SO-2526-0037 | C31: Dorado 4B | E31: Burner | F31: January | G31: 700 | H31: 487 | I31: =G31-H31 -> 213 | K31: 213 | Q31: 0 | R31: 0 | S31: =SUM(J31:P31) -> 213
A32: 31 | B32: BN-SO-2526-0038 | C32: Auriga 3B | E32: Burner | F32: January | G32: 450 | H32: 0 | I32: =G32-H32 -> 450 | K32: 200 | L32: 250 | Q32: 0 | R32: 0 | S32: =SUM(J32:P32) -> 450
A33: 32 | B33: BN-SO-2526-0047 | C33: Asteria 60 BLDC | E33: Chimney | F33: February | G33: 0 | H33: 0 | I33: =G33-H33 -> 0 | Q33: 0 | R33: 0 | S33: =SUM(J33:P33) -> 0 | U33: Plan dropped (50 pcs)
A34: 33 | B34: BN-SO-2526-0048 | C34: Asteria 90 BLDC | E34: Chimney | F34: February | G34: 0 | H34: 0 | I34: =G34-H34 -> 0 | Q34: 0 | R34: 0 | S34: =SUM(J34:P34) -> 0 | U34: Plan dropped (50 pcs)
A35: 34 | B35: BN-SO-2526-0040 | C35: Solaria 3B | E35: Burner | F35: February | G35: 350 | H35: 0 | I35: =G35-H35 -> 350 | N35: 200 | O35: 150 | Q35: 0 | R35: 50 | S35: =SUM(J35:P35) -> 350
A36: 35 | B36: BN-SO-2526-0041 | C36: Solaria 4B | E36: Burner | F36: February | G36: 550 | H36: 0 | I36: =G36-H36 -> 550 | N36: 300 | O36: 250 | Q36: 0 | R36: 50 | S36: =SUM(J36:P36) -> 550
A37: 36 | B37: BN-SO-2526-0039 | C37: Auriga 3B | E37: Burner | F37: February | G37: 450 | H37: 0 | I37: =G37-H37 -> 450 | M37: 450 | Q37: 0 | R37: 0 | S37: =SUM(J37:P37) -> 450
A38: 37 | B38: BN-SO-2526-0038 | C38: Auriga 4B | E38: Burner | F38: February | G38: 800 | H38: 0 | I38: =G38-H38 -> 800 | M38: 200 | N38: 600 | Q38: =35+36 -> 71 | R38: 0 | S38: =SUM(J38:P38) -> 800
A39: 38 | B39: BN-SO-2526-0042 | C39: Arista 60 BLDC | E39: Chimney | F39: February | G39: 0 | H39: 0 | I39: =G39-H39 -> 0 | Q39: 0 | R39: 0 | S39: =SUM(J39:P39) -> 0 | U39: Plan dropped (50 pcs)
A40: 39 | B40: BN-SO-2526-0042 | C40: Arista 90 BLDC | E40: Chimney | F40: February | G40: 0 | H40: 0 | I40: =G40-H40 -> 0 | Q40: 0 | R40: 0 | S40: =SUM(J40:P40) -> 0 | U40: Plan dropped (50 pcs)
...

Sheet Inputs
A1: Sl. No | B1: Work Order | C1: Product | D1: LL | E1: Category | F1: Qtr | G1: Qty | H1: Completed | I1: Pending | J1: Sales Request | K1: WO Creation | L1: WO No | M1: DRG Request Date | N1: DRG Release Date | O1: Costing Sign Off | P1: PO Completion | Q1: LL Item Receiving | R1: Buffer | S1: Sub-Assembly TAT | T1: FG Start | U1: Lead Time | V1: 45992
A2: 1 | B2: BN-SO-2526-0005 | C2: Solaria 4B | E2: Burner | F2: JAS | I2: 0
A3: 2 | B3: BN-SO-2526-0002 | C3: Zyra 4 Burner | E3: Burner | F3: JAS | G3: 290 | H3: 260 | I3: =G3-H3 -> 30
A4: 3 | B4: BN-SO-2526-0049 | C4: Solaria 3B | E4: Burner | F4: OND | G4: 350 | H4: =98+85+40 -> 223 | I4: =G4-H4 -> 127 | L4: =B4 -> BN-SO-2526-0049 | V4: Costing to be finalised
A5: 4 | B5: BN-SO-2526-0026 | C5: Arista 60 | D5: 60 | E5: Chimney | F5: OND | G5: 0 | H5: 0 | I5: =G5-H5 -> 0 | J5: 45859 | K5: 45869 | L5: =B5 -> BN-SO-2526-0026 | M5: 45870 | N5: 45975 | O5: 15-12-2025 | Q5: =P5+D5+15 -> 75 | R5: =Q5+10 -> 85 | S5: =R5+7 -> 92 | T5: =S5+1 -> 93 | U5: =T5-J5-1 -> -45767
A6: 5 | B6: BN-SO-2526-0026 | C6: Arista 90 | D6: 60 | E6: Chimney | F6: OND | G6: 0 | H6: 0 | I6: =G6-H6 -> 0 | J6: 45859 | K6: 45869 | L6: =B6 -> BN-SO-2526-0026 | M6: 45870 | N6: 45975 | O6: 15-12-2025 | Q6: =N6+D6+15 -> 46050 | R6: =Q6+10 -> 46060 | S6: =R6+7 -> 46067 | T6: =S6+1 -> 46068 | U6: =T6-J6-1 -> 208
A7: 6 | B7: BN-SO-2526-0023 | C7: Asteria 60 | D7: 60 | E7: Chimney | F7: OND | G7: 600 | H7: 600 | I7: =G7-H7 -> 0 | J7: 45859 | K7: 45869 | L7: =B7 -> BN-SO-2526-0023 | M7: 45870 | N7: 45908 | O7: 45992 | P7: 46006 | Q7: =N7+D7+15 -> 45983 | R7: =Q7+10 -> 45993 | S7: =R7+7 -> 46000 | T7: =S7+1 -> 46001 | U7: =T7-J7-1 -> 141
A8: 7 | B8: BN-SO-2526-0023 | C8: Asteria 90 | D8: 60 | E8: Chimney | F8: OND | G8: 550 | H8: 550 | I8: =G8-H8 -> 0 | J8: 45859 | K8: 45869 | L8: =B8 -> BN-SO-2526-0023 | M8: 45870 | N8: 45908 | O8: 45992 | P8: 46006 | Q8: =N8+D8+15 -> 45983 | R8: =Q8+10 -> 45993 | S8: =R8+7 -> 46000 | T8: =S8+1 -> 46001 | U8: =T8-J8-1 -> 141
A9: 8 | B9: BN-SO-2526-0028 | C9: Cube | D9: 75 | E9: Chimney | F9: OND | G9: 4000 | H9: 4000 | I9: =G9-H9 -> 0 | J9: 45880 | K9: 45908 | L9: =B9 -> BN-SO-2526-0028 | M9: 45908 | N9: 45905 | O9: 45923 | P9: 46003 | Q9: =N9+D9+15 -> 45995 | R9: =Q9+10 -> 46005 | S9: =R9+7 -> 46012 | T9: =S9+1 -> 46013 | U9: =T9-J9-1 -> 132 | V9: 2000 PO to be shared
A10: 9 | B10: BN-SO-2526-0024 | C10: Elara 60 | D10: 60 | E10: Chimney | F10: OND | G10: 0 | H10: 0 | I10: =G10-H10 -> 0 | J10: 45859 | K10: 45869 | L10: =B10 -> BN-SO-2526-0024 | M10: 45870 | N10: 45988 | O10: 46020 | Q10: =N10+D10+15 -> 46063 | R10: =Q10+10 -> 46073 | S10: =R10+7 -> 46080 | T10: =S10+1 -> 46081 | U10: =T10-J10-1 -> 221 | V10: Costing to be finalised
A11: 10 | B11: BN-SO-2526-0024 | C11: Elara 90 | D11: 60 | E11: Chimney | F11: OND | G11: 0 | H11: 0 | I11: =G11-H11 -> 0 | J11: 45859 | K11: 45869 | L11: =B11 -> BN-SO-2526-0024 | M11: 45870 | N11: 45988 | O11: 46020 | Q11: =N11+D11+15 -> 46063 | R11: =Q11+10 -> 46073 | S11: =R11+7 -> 46080 | T11: =S11+1 -> 46081 | U11: =T11-J11-1 -> 221 | V11: Costing to be finalised
A12: 11 | B12: BN-SO-2526-0025 | C12: Eris 60 | D12: 60 | E12: Chimney | F12: OND | G12: 0 | H12: 0 | I12: =G12-H12 -> 0 | J12: 45859 | K12: 45869 | L12: =B12 -> BN-SO-2526-0025 | M12: 45870 | N12: 45996 | O12: 46020 | Q12: =N12+D12+15 -> 46071 | R12: =Q12+10 -> 46081 | S12: =R12+7 -> 46088 | T12: =S12+1 -> 46089 | U12: =T12-J12-1 -> 229
A13: 12 | B13: BN-SO-2526-0025 | C13: Eris 90 | D13: 60 | E13: Chimney | F13: OND | G13: 0 | H13: 0 | I13: =G13-H13 -> 0 | J13: 45859 | K13: 45869 | L13: =B13 -> BN-SO-2526-0025 | M13: 45870 | N13: 45996 | O13: 46020 | Q13: =N13+D13+15 -> 46071 | R13: =Q13+10 -> 46081 | S13: =R13+7 -> 46088 | T13: =S13+1 -> 46089 | U13: =T13-J13-1 -> 229
A14: 13 | B14: BN-SO-2526-0022 | C14: Orion | D14: 70 | E14: Chimney | F14: OND | G14: 324 | H14: 324 | I14: =G14-H14 -> 0 | J14: 45859 | K14: 45869 | L14: =B14 -> BN-SO-2526-0022 | M14: 45870 | N14: 45908 | P14: 45930 | Q14: =N14+D14+15 -> 45993 | R14: =Q14+10 -> 46003 | S14: =R14+7 -> 46010 | T14: =S14+1 -> 46011 | U14: =T14-J14-1 -> 151
A15: 14 | B15: BN-SO-2526-0019 | C15: Dorado 3B | D15: 65 | E15: Burner | F15: OND | G15: 800 | H15: 800 | I15: =G15-H15 -> 0 | J15: 45859 | K15: 45860 | L15: =B15 -> BN-SO-2526-0019 | M15: 45868 | N15: 45916 | P15: 45924 | Q15: =N15+D15+15 -> 45996 | R15: =Q15+10 -> 46006 | S15: =R15+7 -> 46013 | T15: =S15+1 -> 46014 | U15: =T15-J15-1 -> 154
A16: 15 | B16: BN-SO-2526-0019 | C16: Dorado 4B | D16: 65 | E16: Burner | F16: OND | G16: 1600 | H16: 1600 | I16: =G16-H16 -> 0 | J16: 45859 | K16: 45860 | L16: =B16 -> BN-SO-2526-0019 | M16: 45868 | N16: 45916 | P16: 45924 | Q16: =N16+D16+15 -> 45996 | R16: =Q16+10 -> 46006 | S16: =R16+7 -> 46013 | T16: =S16+1 -> 46014 | U16: =T16-J16-1 -> 154
A17: 16 | B17: BN-SO-2526-0020 | C17: Altair 4B | D17: 70 | E17: Burner | F17: OND | G17: 1255 | H17: 1255 | I17: =G17-H17 -> 0 | J17: 45859 | K17: 45860 | L17: =B17 -> BN-SO-2526-0020 | M17: 45868 | N17: 45948 | P17: 45980 | Q17: =N17+D17+15 -> 46033 | R17: =Q17+10 -> 46043 | S17: =R17+7 -> 46050 | T17: =S17+1 -> 46051 | U17: =T17-J17-1 -> 191
A18: 17 | B18: BN-SO-2526-0042 | C18: Asteria 60 BLDC | E18: Chimney | F18: OND | G18: 50 | H18: 36 | I18: =G18-H18 -> 14 | K18: 45966 | L18: BN-SO-2526-0042 | M18: 45967 | N18: 45975 | V18: Costing to be finalised
A19: 18 | B19: BN-SO-2526-0042 | C19: Asteria 90 BLDC | E19: Chimney | F19: OND | G19: 50 | H19: 40 | I19: =G19-H19 -> 10 | K19: 45966 | L19: BN-SO-2526-0042 | M19: 45967 | N19: 45975 | V19: Costing to be finalised
A20: 19 | B20: BN-SO-2526-0050 | C20: Solaria 4B | E20: Burner | F20: OND | G20: 550 | H20: =185+57+60+98+105 -> 505 | I20: =G20-H20 -> 45 | L20: =B20 -> BN-SO-2526-0050
A21: 20 | B21: BN-SO-2526-0040 | C21: Solaria 3B | E21: Burner | F21: January | G21: 275 | H21: 0 | I21: =G21-H21 -> 275 | K21: 45922 | L21: BN-SO-2526-0040 | M21: 45922 | N21: 45943
A22: 21 | B22: BN-SO-2526-0039 | C22: Auriga 4B | E22: Burner | F22: January | G22: 800 | H22: =65 -> 65 | I22: =G22-H22 -> 735 | K22: 45922 | L22: BN-SO-2526-0039 | M22: 45979 | N22: 46006
A23: 22 | B23: BN-SO-2526-0041 | C23: Solaria 4B | E23: Burner | F23: January | G23: 400 | H23: 0 | I23: =G23-H23 -> 400 | K23: 45922 | L23: BN-SO-2526-0041 | M23: 45922 | N23: 45943
A24: 23 | B24: BN-SO-2526-0029 | C24: Asteria 60 | E24: Chimney | F24: January | G24: 200 | H24: =135+65 -> 200 | I24: =G24-H24 -> 0 | K24: 45922 | L24: BN-SO-2526-0029 | M24: 45922 | N24: Done
A25: 24 | B25: BN-SO-2526-0030 | C25: Asteria 90 | E25: Chimney | F25: January | G25: 0 | H25: 0 | I25: =G25-H25 -> 0 | K25: 45922 | L25: BN-SO-2526-0030 | M25: 45922 | N25: Done | O25: 46006
A26: 25 | B26: BN-SO-2526-0034 | C26: Cube | E26: Chimney | F26: January | G26: 3000 | H26: =167+200+90 -> 457 | I26: =G26-H26 -> 2543 | K26: 45922 | L26: BN-SO-2526-0034 | M26: 45922
A27: 26 | B27: BN-SO-2526-0032 | C27: Eris 60 | E27: Chimney | F27: January | G27: 0 | H27: 0 | I27: =G27-H27 -> 0 | K27: 45922 | L27: BN-SO-2526-0032 | M27: 45922 | N27: 45996
A28: 27 | B28: BN-SO-2526-0033 | C28: Eris 90 | E28: Chimney | F28: January | G28: 0 | H28: 0 | I28: =G28-H28 -> 0 | K28: 45922 | L28: BN-SO-2526-0033 | M28: 45922 | N28: 45996
A29: 28 | B29: BN-SO-2526-0031 | C29: Orion | E29: Chimney | F29: January | G29: 324 | H29: =54+40+35+35+40+32+40+12+34 -> 322 | I29: =G29-H29 -> 2 | K29: 45922 | L29: BN-SO-2526-0031 | M29: 45922 | N29: 45926
A30: 29 | B30: BN-SO-2526-0036 | C30: Dorado 3B | E30: Burner | F30: January | G30: 300 | H30: =243+57 -> 300 | I30: =G30-H30 -> 0 | K30: 45922 | L30: BN-SO-2526-0036 | M30: 45922 | N30: Date to be mentioned
A31: 30 | B31: BN-SO-2526-0037 | C31: Dorado 4B | E31: Burner | F31: January | G31: 700 | H31: =487+77 -> 564 | I31: =G31-H31 -> 136 | K31: 45922 | L31: BN-SO-2526-0037 | M31: 45922 | N31: Date to be mentioned
A32: 32 | B32: BN-SO-2526-0038 | C32: Auriga 3B | E32: Burner | F32: January | G32: 450 | H32: 0 | I32: =G32-H32 -> 450 | K32: 45922 | L32: BN-SO-2526-0038 | M32: 45979 | N32: 46006
A33: 35 | B33: BN-SO-2526-0047 | C33: Asteria 60 BLDC | E33: Chimney | F33: February | G33: 0 | H33: 0 | I33: =G33-H33 -> 0 | K33: 45996 | L33: BN-SO-2526-0047 | M33: TBD
A34: 36 | B34: BN-SO-2526-0048 | C34: Asteria 90 BLDC | E34: Chimney | F34: February | G34: 0 | H34: 0 | I34: =G34-H34 -> 0 | K34: 45996 | L34: BN-SO-2526-0048 | M34: TBD
A35: 37 | B35: BN-SO-2526-0040 | C35: Solaria 3B | E35: Burner | F35: February | G35: 350 | H35: 0 | I35: =G35-H35 -> 350 | K35: 45922 | L35: BN-SO-2526-0040 | M35: 45922
A36: 38 | B36: BN-SO-2526-0041 | C36: Solaria 4B | E36: Burner | F36: February | G36: 550 | H36: 0 | I36: =G36-H36 -> 550 | K36: 45922 | L36: BN-SO-2526-0041 | M36: 45922
A37: 39 | B37: BN-SO-2526-0039 | C37: Auriga 4B | E37: Burner | F37: February | G37: 450 | H37: 0 | I37: =G37-H37 -> 450 | K37: 45922 | L37: BN-SO-2526-0039 | M37: 45979
A38: 40 | B38: BN-SO-2526-0038 | C38: Auriga 3B | E38: Burner | F38: February | G38: 800 | H38: 0 | I38: =G38-H38 -> 800 | K38: 45922 | L38: BN-SO-2526-0038 | M38: 45979
A39: 41 | B39: BN-SO-2526-0042 | C39: Arista 60 BLDC | E39: Chimney | F39: February | G39: 0 | H39: 0 | I39: =G39-H39 -> 0 | J39: jm | K39: 45966 | L39: BN-SO-2526-0042 | M39: 45967 | N39: 45975
A40: 42 | B40: BN-SO-2526-0042 | C40: Arista 90 BLDC | E40: Chimney | F40: February | G40: 0 | H40: 0 | I40: =G40-H40 -> 0 | K40: 45966 | L40: BN-SO-2526-0042 | M40: 45967 | N40: 45975
...

Sheet Plan-JAS
A1: a | B1: Product | C1: Check | D1: Pending WO | E1: Category | F1: July | G1: 15 | H1: 16 | I1: 17 | J1: 18 | K1: 19 | L1: 20 | M1: 21 | N1: 22 | O1: 23 | P1: 24 | Q1: 25 | R1: 26 | S1: 27 | T1: 28 | U1: 29 | V1: 30 | W1: 31 | X1: Aug | Y1: 2 | Z1: 3 | AA1: 4 | AB1: 5 | AC1: 6 | AD1: 7 | AE1: 8 | AF1: 9 | AG1: 10 | AH1: 11 | AI1: 12 | AJ1: 13 | AK1: 14 | AL1: 15 | AM1: 16 | AN1: 17 | AO1: 18 | AP1: 19 | AQ1: 20 | AR1: 21 | AS1: 22 | AT1: 23 | AU1: 24 | AV1: 25 | AW1: 26 | AX1: 27 | AY1: 28 | AZ1: 29 | BA1: 30 | BB1: 31 | BC1: Sep | BD1: 2 | BE1: 3 | BF1: 4 | BG1: 5 | BH1: 6 | BI1: 7 | BJ1: 8 | BK1: 9 | BL1: 10 | BM1: 11 | BN1: 12 | BO1: 13 | BP1: 14 | BQ1: 15 | BR1: 16 | BS1: 17 | BT1: 18 | BU1: 19 | BV1: 20 | BW1: 21 | BX1: 22 | BY1: 23 | BZ1: 24 | CA1: 25 | CB1: 26 | CC1: 27 | CD1: 28 | CE1: 29 | CF1: 30 | CG1: Nov
A2: a | B2: Arista 60 | C2: =SUM(F2:XI2)-D2 -> 0 | D2: 600 | E2: Chimney | T2: 20 | V2: 50 | W2: 50 | X2: 50 | Y2: 50 | AA2: 50 | AB2: 30 | AC2: 0 | AR2: 100 | AS2: 100 | AT2: 100
A3: a | B3: Arista 90 | C3: =SUM(F3:XI3)-D3 -> 0 | D3: 600 | E3: Chimney | T3: 20 | V3: 50 | W3: 50 | X3: 50 | Y3: 50 | AA3: 50 | AB3: 30 | AC3: 0 | AR3: 100 | AS3: 100 | AT3: 100
A4: a | B4: Asteria 60 | C4: =SUM(F4:XI4)-D4 -> 0 | D4: 600 | E4: Chimney | U4: 50 | V4: 110 | W4: 110 | X4: 110 | Y4: 110 | AA4: 110
A5: a | B5: Asteria 90 | C5: =SUM(F5:XI5)-D5 -> 0 | D5: 550 | E5: Chimney | O5: 0 | P5: 80 | Q5: 110 | R5: 110 | S5: 80 | T5: 110 | U5: 60
A6: a | B6: Auriga 3B | C6: =SUM(F6:XI6)-D6 -> 0 | D6: =300+200+500 -> 1000 | E6: Burner | F6: 95 | G6: 50 | H6: 50 | M6: 50 | N6: 55 | W6: 75 | X6: 75 | Y6: 75 | AA6: 75 | AB6: 75 | AC6: 75 | AD6: 75 | AE6: 75 | AF6: 75 | AH6: 25
A7: a | B7: Auriga 4B | C7: =SUM(F7:XI7)-D7 -> 0 | D7: =300+200+500 -> 1000 | E7: Burner | F7: 112 | G7: 50 | H7: 50 | M7: 45 | N7: 43 | W7: 75 | X7: 75 | Y7: 75 | AA7: 75 | AB7: 75 | AC7: 75 | AD7: 75 | AE7: 75 | AF7: 75 | AH7: 25
A8: a | B8: Cube 60 | C8: =SUM(F8:XI8)-D8 -> 0 | D8: =400+2100 -> 2500 | E8: Chimney | F8: 320 | V8: 40 | W8: 40 | Y8: 80 | AA8: 80 | AB8: 80 | AC8: 80 | AD8: 80 | AE8: 100 | AO8: 100 | AP8: 100 | AQ8: 100 | AR8: 100 | AS8: 100 | AT8: 100 | AV8: 100 | AW8: 100 | AX8: 100 | AY8: 100 | AZ8: 100 | BA8: 100 | BC8: 100 | BD8: 100 | BE8: 100 | BF8: 100
A9: a | B9: Dorado 3B | C9: =SUM(F9:XI9)-D9 -> -800 | D9: =420+800+800 -> 2020 | E9: Burner | K9: =90-39 -> 51 | O9: 92 | P9: 92 | Q9: 92 | R9: 93 | AO9: 130 | AP9: 130 | AQ9: 130 | AR9: 130 | AS9: 130 | AT9: 150
A10: a | B10: Dorado 4B | C10: =SUM(F10:XI10)-D10 -> -1600 | D10: =780+1600+1600 -> 3980 | E10: Burner | H10: 115 | I10: 90 | J10: 90 | K10: 90 | O10: 99 | P10: 99 | Q10: 99 | R10: 98 | AO10: 150 | AP10: 150 | AQ10: 150 | AR10: 150 | AS10: 150 | AT10: 150 | AV10: 150 | AW10: 150 | AX10: 150 | AY10: 150 | AZ10: 100
A11: a | B11: Dorado Plus | C11: =SUM(F11:XI11)-D11 -> 0 | D11: 297 | E11: Burner | T11: 90 | U11: 97 | V11: 110
A12: a | B12: Dorado Premium | C12: =SUM(F12:XI12)-D12 -> -1400 | D12: =377+650+1400 -> 2427 | E12: Burner | F12: 203 | I12: 90 | J12: 55 | O12: 29 | AW12: 50 | AX12: 80 | AY12: 80 | AZ12: 80 | BA12: 80 | BC12: 80 | BD12: 80 | BE12: 80 | BF12: 40
A13: a | B13: Elara 60 | C13: =SUM(F13:XI13)-D13 -> 0 | D13: =100+500 -> 600 | E13: Chimney | F13: 11 | G13: 10 | H13: 18 | I13: 8 | O13: 15 | P13: 25 | Q13: 30 | R13: 30 | AE13: 50 | AF13: 53 | AI13: 50 | AJ13: 50 | AK13: 50 | AL13: 50 | AM13: 50 | AR13: 100
A14: a | B14: Elara 90 | C14: =SUM(F14:XI14)-D14 -> 0 | D14: 600 | E14: Chimney | F14: 16 | G14: 10 | H14: 21 | I14: 11 | Q14: 22 | R14: 20 | AB14: 100 | AC14: 100 | AD14: 100 | AE14: 100 | AF14: 100
A15: a | B15: Eris 60 | C15: =SUM(F15:XI15)-D15 -> 0 | D15: 600 | E15: Chimney | AI15: 50 | AJ15: 50 | AK15: 50 | AL15: 50 | AM15: 50 | AN15: 100 | AO15: 100 | AP15: 100 | AQ15: 50
A16: a | B16: Eris 90 | C16: =SUM(F16:XI16)-D16 -> 0 | D16: 600 | E16: Chimney | AE16: 100 | AF16: 100 | AH16: 100 | AI16: 100 | AJ16: 100 | AK16: 100
A17: a | B17: Orion | C17: =SUM(F17:XI17)-D17 -> -324 | D17: =320+324 -> 644 | E17: Chimney | BJ17: 60 | BK17: 60 | BL17: 60 | BM17: 60 | BN17: 60 | BO17: 20
A18: a | B18: Solaria 3B | C18: =SUM(F18:XI18)-D18 -> 0 | D18: 0 | E18: Burner
A19: a | B19: Solaria 4B | C19: =SUM(F19:XI19)-D19 -> 0 | D19: 150 | E19: Burner | AO19: 10 | AP19: 20 | AQ19: 30 | AR19: 30 | AS19: 30 | AT19: 30
A20: a | B20: Zyra | C20: =SUM(F20:XI20)-D20 -> 0 | D20: 290 | E20: Burner | AH20: 10 | AI20: 40 | AJ20: 40 | AK20: 40 | AL20: 40 | AM20: 40 | AO20: 40 | AP20: 40
A21: b | B21: Arista 60 | D21: 600 | E21: Chimney | AA21: 20 | AC21: 100 | AD21: 100 | AE21: 80 | AH21: 40 | AI21: 50 | AO21: 100
A22: b | B22: Arista 90 | D22: 600 | E22: Chimney | AA22: 20 | AC22: 100 | AD22: 100 | AE22: 80 | AH22: 60 | AI22: 50 | AO22: 96
A23: b | B23: Asteria 60 | D23: 600 | E23: Chimney | AC23: =113+20 -> 133 | AE23: 27 | AF23: 50 | AH23: 72 | AX23: 46 | AZ23: 90 | BC23: 60 | BD23: =24*4 -> 96 | BE23: =24*4 -> 96 | BG23: 9 | BJ23: 30 | BK23: 60 | BL23: 65 | BT23: 15
A24: b | B24: Asteria 90 | D24: 550 | E24: Chimney | V24: 55 | W24: 55 | X24: 90 | AH24: 30 | AI24: 70 | AM24: 70 | AR24: 70 | AW24: 70 | AY24: 98 | BG24: 64 | BH24: 36 | BM24: 64 | BN24: 36 | BQ24: 10 | BR24: 70 | BS24: 71 | BT24: 20
A25: b | B25: Auriga 3B | D25: =300+200+500 -> 1000 | E25: Burner | F25: =24+20 -> 44 | G25: 22 | H25: 52 | M25: 50 | N25: 55 | O25: 0 | P25: 0 | Q25: 0 | R25: 0 | T25: 42 | X25: 75 | Y25: 75 | AA25: 75 | AB25: 75 | AC25: 75 | AD25: 75 | AE25: 25 | AF25: 25 | AJ25: 75 | AK25: 75 | AL25: 75 | AM25: 75 | AP25: 60 | AQ25: 60 | AR25: 60 | AS25: 60 | AT25: 60 | AV25: 120 | AW25: 7
A26: b | B26: Auriga 4B | D26: =300+200+500 -> 1000 | E26: Burner | F26: 30 | G26: 30 | H26: 42 | M26: 45 | N26: 43 | T26: 29 | X26: 75 | Y26: 75 | AA26: 75 | AB26: 75 | AC26: 75 | AD26: 75 | AE26: 25 | AF26: 25 | AH26: 50 | AI26: 50 | AJ26: 75 | AK26: 75 | AL26: 75 | AM26: 75 | AP26: 60 | AQ26: 60 | AR26: 60 | AS26: 60 | AT26: 60 | AW26: 28
A27: b | B27: Cube 60 | D27: =400+2100 -> 2500 | E27: Chimney | V27: 40 | W27: 40 | Y27: 80 | AC27: 100 | AD27: 100 | AE27: 100 | AF27: 100 | AH27: 75 | AI27: 75 | AJ27: 75 | AK27: 75 | AL27: 75 | AM27: 75 | AO27: 75 | AP27: 75 | AQ27: 75 | AR27: 75 | AS27: 75 | AT27: 75 | AV27: 100 | AW27: 120 | AX27: 60 | AY27: 120 | AZ27: 120 | BA27: 120 | BJ27: 80 | BK27: 80 | BL27: 80 | BM27: 80 | BN27: 80 | BO27: 80 | BQ27: 80 | BR27: 80 | BS27: 80 | CB27: 80 | CC27: 80 | CD27: 80 | CE27: 69
A28: b | B28: Dorado 3B | D28: =420+800+800 -> 2020 | E28: Burner | J28: 33 | K28: 84 | O28: 92 | P28: 92 | Q28: 92 | R28: 93 | AE28: 150 | AH28: 50 | AI28: 50 | BC28: =120+21+75 -> 216 | BD28: 84 | BG28: 280 | BL28: 150 | BN28: 150 | BQ28: 153 | BS28: 60 | BY28: 32 | CF28: 8
A29: b | B29: Dorado 4B | D29: =780+1600+1600 -> 3980 | E29: Burner | I29: 90 | J29: 97 | K29: 90 | O29: 99 | P29: 99 | Q29: 99 | R29: 98 | AF29: 150 | AH29: 50 | AI29: 50 | BC29: =120+26+75 -> 221 | BD29: =75+150 -> 225 | BE29: 280 | BF29: 280 | BH29: 280 | BI29: 150 | BK29: 25 | BM29: 150 | BO29: 150 | BR29: 150 | BS29: 59 | BY29: 28 | CF29: 21
A30: b | B30: Dorado Plus | D30: 297 | E30: Burner | U30: 90 | V30: 97 | W30: 110 | AJ30: 42 | AR30: zz | BX30: 5
A31: b | B31: Dorado Premium | D31: =377+650+1400 -> 2427 | E31: Burner | I31: 69 | J31: 46 | O31: 29 | AX31: 50 | AY31: 150 | AZ31: 150 | BA31: 150 | BF31: 90 | BJ31: 150 | BK31: 124 | BV31: 62 | BX31: 62
A32: b | B32: Elara 60 | D32: =100+500 -> 600 | E32: Chimney | F32: 11 | G32: 17 | H32: 15 | I32: 8 | J32: 10 | Q32: 0 | R32: 0 | T32: 50 | U32: 30 | V32: 20 | AE32: 50 | AF32: 53 | AI32: 50 | AJ32: 100 | AK32: 100 | AL32: 100 | AM32: 50 | AP32: 100 | AQ32: 100 | AS32: 100 | AT32: 100 | AV32: 100 | AW32: 168 | BT32: 32
A33: b | B33: Elara 90 | D33: =40+500 -> 540 | E33: Chimney | F33: 16 | G33: 10 | H33: 15 | I33: 11 | J33: 7 | AJ33: 100 | AK33: 100 | AP33: 50 | AQ33: 100 | AR33: 50 | AS33: 100 | CC33: 100
A34: b | B34: Eris 60 | D34: 600 | E34: Chimney | AV34: 80 | AW34: 60 | AY34: 60 | AZ34: 60 | BA34: 120 | BF34: =135-23 -> 112 | BX34: 32 | BY34: 75 | BZ34: 75 | CA34: 75 | CB34: 50 | CC34: 32 | CD34: 32 | CE34: 75 | CF34: 19
A35: b | B35: Eris 90 | D35: 600 | E35: Chimney | AP35: 100 | AQ35: 50 | AR35: 100 | AS35: 50 | CC35: 95
A36: b | B36: Orion | D36: =320+320 -> 640 | E36: Chimney | BD36: 36 | BE36: 36 | BG36: 36 | BJ36: 29 | BK36: 60 | BL36: 60 | BM36: 60 | BN36: 72 | BQ36: 30 | CF36: 40 | CG36: 20
A37: b | B37: Solaria 3B | D37: 0 | E37: Burner
A38: b | B38: Solaria 4B | D38: 150 | E38: Burner | BT38: 40 | BU38: 40 | BV38: 50 | BX38: 40 | BY38: 40 | BZ38: 40
A39: b | B39: Zyra | D39: 290 | E39: Burner | BU39: 100 | BV39: 100 | BX39: 50 | CB39: 50 | CC39: 100 | CD39: 90
A40: c | B40: Arista 60 | D40: 600 | E40: Chimney | AB40: 20 | AC40: 35 | AD40: 0 | AE40: 35 | AF40: 31 | AG40: 39 | AI40: 40 | AJ40: 0 | AK40: 0 | AL40: 0 | AM40: 0 | AN40: 0 | AO40: 100
...

Sheet Plan-OND
A1: Sl. NO | B1: Model | C1: Category | D1: OND | E1: CMO | F1: OCT Planned | G1: OCT W1 | H1: OCT W2 | I1: OCT W3 | J1: OCT W4 | K1: OCT W5 | L1: 17th Nov Pending | AK1: Nov | AL1: Nov W1 | AM1: Nov W2 | AN1: Nov W3 | AO1: Nov W4 | BO1: Dec | BP1: DEC W1 | BQ1: DEC W2 | BR1: DEC W3 | BS1: DEC W4 | BT1: DEC W5
A2: 1 | B2: Arista 60 | C2: Chimney | D2: =F2+AK2+BO2 -> 200 | F2: =SUM(G2:K2) -> 0 | AK2: =SUM(AL2:AO2) -> 0 | BO2: =SUM(BP2:BT2) -> 200 | BQ2: 200
A3: 2 | B3: Arista 90 | C3: Chimney | D3: =F3+AK3+BO3 -> 200 | F3: =SUM(G3:K3) -> 0 | AK3: =SUM(AL3:AO3) -> 0 | BO3: =SUM(BP3:BT3) -> 200 | BQ3: 200
A4: 3 | B4: Asteria 60 | C4: Chimney | D4: =F4+AK4+BO4 -> 600 | F4: =SUM(G4:K4) -> 200 | I4: 200 | L4: 20 | AK4: =SUM(AL4:AO4) -> 200 | AL4: 200 | BO4: =SUM(BP4:BT4) -> 200 | BP4: 200
A5: 4 | B5: Asteria 90 | C5: Chimney | D5: =F5+AK5+BO5 -> 550 | F5: =SUM(G5:K5) -> 200 | I5: 200 | L5: 100 | AK5: =SUM(AL5:AO5) -> 200 | AM5: 200 | BO5: =SUM(BP5:BT5) -> 150 | BQ5: 150
A6: 5 | B6: Cube | C6: Chimney | D6: =F6+AK6+BO6 -> 4000 | F6: =SUM(G6:K6) -> 0 | AK6: =SUM(AL6:AO6) -> 4000 | AL6: 1000 | AM6: 1000 | AN6: 1000 | AO6: 1000 | BO6: =SUM(BP6:BT6) -> 0
A7: 6 | B7: Elara 60 | C7: Chimney | D7: =F7+AK7+BO7 -> 250 | F7: =SUM(G7:K7) -> 0 | AK7: =SUM(AL7:AO7) -> 0 | BO7: =SUM(BP7:BT7) -> 250 | BR7: 150 | BT7: 100
A8: 7 | B8: Elara 90 | C8: Chimney | D8: =F8+AK8+BO8 -> 250 | F8: =SUM(G8:K8) -> 0 | AK8: =SUM(AL8:AO8) -> 0 | BO8: =SUM(BP8:BT8) -> 250 | BR8: 150 | BT8: 100
A9: 8 | B9: Eris 60 | C9: Chimney | D9: =F9+AK9+BO9 -> 0 | F9: =SUM(G9:K9) -> 0 | AK9: =SUM(AL9:AO9) -> 0 | BO9: =SUM(BP9:BT9) -> 0
A10: 9 | B10: Eris 90 | C10: Chimney | D10: =F10+AK10+BO10 -> 0 | F10: =SUM(G10:K10) -> 0 | AK10: =SUM(AL10:AO10) -> 0 | BO10: =SUM(BP10:BT10) -> 0
A11: 10 | B11: Orion | C11: Chimney | D11: =F11+AK11+BO11 -> 324 | F11: =SUM(G11:K11) -> 324 | I11: 324 | L11: 324 | AK11: =SUM(AL11:AO11) -> 0 | BO11: =SUM(BP11:BT11) -> 0
A12: 11 | B12: Dorado 3B | C12: Burner | D12: =F12+AK12+BO12 -> 800 | F12: =SUM(G12:K12) -> 300 | H12: 300 | AK12: =SUM(AL12:AO12) -> 300 | AL12: 300 | BO12: =SUM(BP12:BT12) -> 200 | BP12: 200
A13: 12 | B13: Dorado 4B | C13: Burner | D13: =F13+AK13+BO13 -> 1600 | F13: =SUM(G13:K13) -> 600 | I13: 600 | AK13: =SUM(AL13:AO13) -> 500 | AL13: 500 | BO13: =SUM(BP13:BT13) -> 500 | BP13: 500
A14: 13 | B14: Altair 4B | C14: Burner | D14: 1255 | F14: =SUM(G14:K14) -> 0 | AK14: =SUM(AL14:AO14) -> 700 | AM14: 400 | AN14: 300 | BO14: =SUM(BP14:BT14) -> 700 | BQ14: 400 | BR14: 300
A15: 14 | B15: Solaria 3B | C15: Burner | D15: =F15+AK15+BO15 -> 350 | F15: =SUM(G15:K15) -> 0 | AK15: =SUM(AL15:AO15) -> 0 | BO15: 350
A16: 15 | B16: Solaria 4B | C16: Burner | D16: =F16+AK16+BO16 -> 550 | F16: =SUM(G16:K16) -> 0 | AK16: =SUM(AL16:AO16) -> 0 | BO16: 550
A17: 16 | B17: Zyra | C17: Burner | D17: =F17+AK17+BO17 -> 0 | F17: =SUM(G17:K17) -> 0 | AK17: =SUM(AL17:AO17) -> 0 | BO17: =SUM(BP17:BT17) -> 0
A18: 17 | B18: Auriga 3B | C18: Burner | D18: =F18+AK18+BO18 -> 250 | F18: =SUM(G18:K18) -> 250 | H18: 250 | AK18: =SUM(AL18:AO18) -> 0 | BO18: =SUM(BP18:BT18) -> 0 | BP18: 0
A19: 18 | B19: Auriga 4B | C19: Burner | D19: =F19+AK19+BO19 -> 250 | F19: =SUM(G19:K19) -> 250 | H19: 250 | AK19: =SUM(AL19:AO19) -> 0 | BO19: =SUM(BP19:BT19) -> 0 | BP19: 0
B20: TOTAL | D20: =SUM(D2:D19) -> 11429 | F20: =SUM(F4:F19) -> 2124 | AK20: =SUM(AK4:AK19) -> 5900 | BO20: =SUM(BO2:BO19) -> 3550
A21: a | B21: Product | C21: Check | D21: Pending WO | E21: Category | F21: Oct | G21: 2 | H21: 3 | I21: 4 | J21: 5 | K21: 6 | L21: 7 | M21: 8 | N21: 9 | O21: 10 | P21: 11 | Q21: 12 | R21: 13 | S21: 14 | T21: 15 | U21: 16 | V21: 17 | W21: 18 | X21: 19 | Y21: 20 | Z21: 21 | AA21: 22 | AB21: 23 | AC21: 24 | AD21: 25 | AE21: 26 | AF21: 27 | AG21: 28 | AH21: 29 | AI21: 30 | AJ21: 31 | AK21: Nov | AL21: 2 | AM21: 3 | AN21: 4 | AO21: 5 | AP21: 6 | AQ21: 7 | AR21: 8 | AS21: 9 | AT21: 10 | AU21: 11 | AV21: 12 | AW21: 13 | AX21: 14 | AY21: 15 | AZ21: 16 | BA21: 17 | BB21: 18 | BC21: 19 | BD21: 20 | BE21: 21 | BF21: 22 | BG21: 23 | BH21: 24 | BI21: 25 | BJ21: 26 | BK21: 27 | BL21: 28 | BM21: 29 | BN21: 30 | BO21: DEC | BP21: 2 | BQ21: 3 | BR21: 4 | BS21: 5 | BT21: 6 | BU21: 7 | BV21: 8 | BW21: 9 | BX21: 10 | BY21: 11 | BZ21: 12 | CA21: 13 | CB21: 14 | CC21: 15 | CD21: 16 | CE21: 17 | CF21: 18 | CG21: 19 | CH21: 20 | CI21: 21 | CJ21: 22 | CK21: 23 | CL21: 24 | CM21: 25 | CN21: 26 | CO21: 27 | CP21: 28 | CQ21: 29 | CR21: 30 | CS21: 31
A22: 1 | B22: Arista 60 | D22: 200 | E22: Chimney
A23: 2 | B23: Arista 90 | D23: 200 | E23: Chimney
A24: 3 | B24: Asteria 60 | D24: 600 | E24: Chimney | W24: 200 | AU24: 200 | BV24: 100 | BW24: 100 | CC24: 100 | CD24: 100
A25: 4 | B25: Asteria 90 | D25: 550 | E25: Chimney | Y25: 200 | AV25: 200 | BX25: 100 | BY25: 100 | CE25: 150
A26: 5 | B26: Cube 60 | D26: 4000 | E26: Chimney | T26: 100 | U26: 100 | V26: 100 | W26: 200 | AM26: 100 | AN26: 100 | AO26: 100 | AP26: 100 | AQ26: 100 | AW26: 200 | AX26: 200 | AY26: 200 | BA26: 200 | BB26: 200 | BC26: 200 | BD26: 200 | BE26: 200 | BF26: 200 | BH26: 40 | BI26: 40 | BJ26: 47 | BK26: 200 | BL26: 200 | BM26: 200 | BO26: 7 | BS26: 300 | BT26: 200 | BZ26: 300 | CA26: 200 | CC26: 200 | CD26: 200 | CE26: 200 | CF26: 200 | CG26: 200 | CJ26: 200 | CK26: 200 | CL26: 200 | CM26: 200 | CN26: 200 | CQ26: 200 | CR26: 200
A27: 6 | B27: Elara 60 | D27: 250 | E27: Chimney | BP27: 20 | BQ27: 20 | BS27: 27 | CP27: 150 | CS27: 100
A28: 7 | B28: Elara 90 | D28: 250 | E28: Chimney | CQ28: 100 | CR28: 150
A29: 8 | B29: Eris 60 | D29: 0 | E29: Chimney | BP29: 30 | BQ29: 30 | BR29: 30 | BS29: 40 | BT29: 32 | BV29: 40 | BW29: 40
A30: 9 | B30: Eris 90 | D30: 0 | E30: Chimney
A31: 10 | B31: Orion | D31: 324 | E31: Chimney | AT31: 40 | AU31: 40 | AV31: 40 | AW31: 40 | AX31: 40 | AY31: 44 | BA31: 40 | BB31: 40 | BH31: 40 | BI31: 40 | BJ31: 24 | BO31: 40 | CH31: 33
A32: 11 | B32: Dorado 3B | D32: 800 | E32: Burner | S32: 200 | T32: 100 | AM32: 150 | AN32: 150 | CC32: 150 | CD32: 50
A33: 12 | B33: Dorado 4B | D33: 1600 | E33: Burner | T33: 100 | U33: 150 | V33: 200 | W33: 150 | AO33: 100 | AP33: 100 | AQ33: 100 | AR33: 100 | AT33: 100 | CD33: 100 | CE33: 150 | CF33: 150 | CG33: 100
A34: 13 | B34: Dorado Premium | D34: 1255 | E34: Burner | BB34: 100 | BC34: 100 | BD34: 100 | BE34: 150 | BF34: 150 | BH34: 100 | BI34: 100 | BJ34: 100 | BK34: 100 | BL34: 150 | BM34: 150 | BO34: 70 | BP34: 70 | BQ34: 70 | BR34: 70 | BS34: 70 | BT34: 70 | BV34: 100 | BW34: 100 | BX34: 100 | BY34: 100 | BZ34: 100 | CA34: 105
A35: 14 | B35: Solaria 3B | D35: 350 | E35: Burner | CM35: 120 | CN35: 120 | CO35: 120 | CP35: 120
A36: 15 | B36: Solaria 4B | D36: 550 | E36: Burner | BR36: 30 | CJ36: 100 | CK36: 100 | CL36: 100 | CQ36: 120 | CR36: 120 | CS36: 120
A37: 16 | B37: Zyra | D37: 0 | E37: Burner | BZ37: 70
A38: 17 | B38: Auriga 3B | D38: 250 | E38: Burner | M38: 50 | N38: 100 | P38: 100
A39: 18 | B39: Auriga 4B | D39: 250 | E39: Burner | M39: 50 | O39: 100 | R39: 100
A40: 19 | B40: Asteria 60 BLDC | D40: 50 | E40: Chimney | BQ40: 50
...

Sheet Plan-JFM
A1: Sl. NO | B1: Model | C1: Category | D1: JFM | E1: CMO | F1: JAN | G1: JAN W1 | H1: JAN W2 | I1: JAN W3 | J1: JAN W4 | K1: JAN W5 | AK1: Feb | AL1: FEB W1 | AM1: FEB W2 | AN1: FEB W3 | AO1: FEB W4 | BM1: MAR | BN1: MAR W1 | BO1: MAR W2 | BP1: MAR W3 | BQ1: MAR W4 | BR1: MAR W5
A2: 1 | B2: Asteria 60 | C2: Chimney | D2: 545 | F2: =SUM(G2:K2) -> 545 | G2: 145 | I2: 400 | AK2: =SUM(AL2:AO2) -> 200 | AL2: 200 | BM2: =SUM(BN2:BR2) -> 200 | BN2: 200
A3: 2 | B3: Asteria 90 | C3: Chimney | D3: 0 | F3: =SUM(G3:K3) -> 400 | I3: 400 | AK3: =SUM(AL3:AO3) -> 225 | AL3: 225 | BM3: =SUM(BN3:BR3) -> 225 | BN3: 225
A4: 3 | B4: Orion | C4: Chimney | D4: =F4+AK4+BM4 -> 972 | F4: =SUM(G4:K4) -> 324 | I4: 324 | AK4: =SUM(AL4:AO4) -> 324 | AL4: 324 | BM4: =SUM(BN4:BR4) -> 324 | BN4: 324
A5: 4 | B5: Altair 4B | C5: Burner | D5: 275 | F5: =SUM(G5:K5) -> 875 | H5: 200 | I5: 75 | K5: 600 | AK5: =SUM(AL5:AO5) -> 600 | AL5: 300 | AM5: 300 | BM5: =SUM(BN5:BR5) -> 600 | BN5: 300 | BO5: 300
A6: 5 | B6: Dorado 3B | C6: Burner | D6: 1120 | F6: =SUM(G6:K6) -> 320 | H6: 20 | J6: 300 | AK6: =SUM(AL6:AO6) -> 275 | AL6: 275 | BM6: =SUM(BN6:BR6) -> 375 | BN6: 375
A7: 6 | B7: Dorado 4B | C7: Burner | D7: 2442 | F7: =SUM(G7:K7) -> 842 | H7: 142 | J7: 600 | K7: 100 | AK7: =SUM(AL7:AO7) -> 600 | AL7: 300 | AM7: 300 | BM7: =SUM(BN7:BR7) -> 900 | BN7: 400 | BO7: 300 | BP7: 200
A8: 7 | B8: Elara 60 | C8: Chimney | D8: 0 | F8: =SUM(G8:K8) -> 250 | J8: 250 | AK8: =SUM(AL8:AO8) -> 150 | AL8: 150 | BM8: =SUM(BN8:BR8) -> 210 | BN8: 210
A9: 8 | B9: Elara 90 | C9: Chimney | D9: 0 | F9: =SUM(G9:K9) -> 250 | J9: 250 | AK9: =SUM(AL9:AO9) -> 205 | AL9: 205 | BM9: =SUM(BN9:BR9) -> 275 | BN9: 275
A10: 9 | B10: Eris 60 | C10: Chimney | D10: 200 | F10: =SUM(G10:K10) -> 200 | I10: 200 | AK10: =SUM(AL10:AO10) -> 150 | AL10: 150 | BM10: =SUM(BN10:BR10) -> 185 | BN10: 185
A11: 10 | B11: Eris 90 | C11: Chimney | D11: 200 | F11: =SUM(G11:K11) -> 250 | I11: 250 | AK11: =SUM(AL11:AO11) -> 205 | AL11: 205 | BM11: =SUM(BN11:BR11) -> 250 | BN11: 250
A12: 11 | B12: Arista 60 | C12: Chimney | D12: 0 | F12: =SUM(G12:K12) -> 200 | I12: 200 | AK12: =SUM(AL12:AO12) -> 124 | AL12: 124 | BM12: =SUM(BN12:BR12) -> 161 | BN12: 161
A13: 12 | B13: Arista 90 | C13: Chimney | D13: 0 | F13: =SUM(G13:K13) -> 200 | I13: 200 | AK13: =SUM(AL13:AO13) -> 124 | AL13: 124 | BM13: =SUM(BN13:BR13) -> 161 | BN13: 161
A14: 13 | B14: Cube | C14: Chimney | D14: 19314 | F14: =SUM(G14:K14) -> 4314 | G14: 300 | H14: 1014 | J14: 600 | K14: 2400 | AK14: =SUM(AL14:AO14) -> 7500 | AL14: 1500 | AM14: 2000 | AN14: 2000 | AO14: 2000 | BM14: =SUM(BN14:BR14) -> 7500 | BN14: 1000 | BO14: 1500 | BP14: 2000 | BQ14: 2000 | BR14: 1000
A15: 14 | B15: Auriga 3B | C15: Burner | D15: 1500 | F15: =SUM(G15:K15) -> 400 | J15: 200 | K15: 200 | AK15: =SUM(AL15:AO15) -> 510 | AL15: 510 | BM15: =SUM(BN15:BR15) -> 750 | BN15: 400 | BO15: 350
A16: 15 | B16: Auriga 4B | C16: Burner | D16: 1600 | F16: =SUM(G16:K16) -> 600 | J16: 200 | K16: 400 | AK16: =SUM(AL16:AO16) -> 764 | AL16: 500 | AM16: 264 | BM16: =SUM(BN16:BR16) -> 1100 | BN16: 600 | BO16: 500
A17: 16 | B17: Solaria 3B | C17: Burner | D17: 1425 | F17: =SUM(G17:K17) -> 625 | H17: 200 | I17: 300 | J17: 125 | AK17: =SUM(AL17:AO17) -> 210 | AL17: 210 | BM17: =SUM(BN17:BR17) -> 300 | BN17: 300
A18: 17 | B18: Solaria 4B | C18: Burner | D18: 1500 | F18: =SUM(G18:K18) -> 950 | H18: 300 | I18: 300 | J18: 350 | AK18: =SUM(AL18:AO18) -> 240 | AL18: 240 | BM18: =SUM(BN18:BR18) -> 360 | BN18: 360
A19: 18 | B19: Zyra | C19: Burner | D19: 30 | F19: =SUM(G19:K19) -> 30 | J19: 30
A20: 19 | B20: Asteria 60 BLDC | C20: Chimney | D20: 0 | F20: =SUM(G20:K20) -> 50 | H20: 50
A21: 20 | B21: Asteria 90 BLDC | C21: Chimney | D21: 0 | F21: =SUM(G21:K21) -> 50 | H21: 50
A22: 21 | B22: Arista 60 BLDC | C22: Chimney | D22: 0 | F22: =SUM(G22:K22) -> 50 | K22: 50
A23: 22 | B23: Arista 90 BLDC | C23: Chimney | D23: 0 | F23: =SUM(G23:K23) -> 50 | K23: 50
B24: TOTAL | D24: =SUM(D2:D23) -> 31123 | F24: =SUM(F2:F23) -> 11775 | AK24: =SUM(AK2:AK18) -> 12406 | BM24: =SUM(BM2:BM18) -> 13876
A25: a | B25: Product | C25: Check | D25: Pending WO | E25: Category | F25: JAN | G25: 2 | H25: 3 | I25: 4 | J25: 5 | K25: 6 | L25: 7 | M25: 8 | N25: 9 | O25: 10 | P25: 11 | Q25: 12 | R25: 13 | S25: 14 | T25: 15 | U25: 16 | V25: 17 | W25: 18 | X25: 19 | Y25: 20 | Z25: 21 | AA25: 22 | AB25: 23 | AC25: 24 | AD25: 25 | AE25: 26 | AF25: 27 | AG25: 28 | AH25: 29 | AI25: 30 | AJ25: 31 | AK25: FEB | AL25: 2 | AM25: 3 | AN25: 4 | AO25: 5 | AP25: 6 | AQ25: 7 | AR25: 8 | AS25: 9 | AT25: 10 | AU25: 11 | AV25: 12 | AW25: 13 | AX25: 14 | AY25: 15 | AZ25: 16 | BA25: 17 | BB25: 18 | BC25: 19 | BD25: 20 | BE25: 21 | BF25: 22 | BG25: 23 | BH25: 24 | BI25: 25 | BJ25: 26 | BK25: 27 | BL25: 28 | BM25: MAR | BN25: 2 | BO25: 3 | BP25: 4 | BQ25: 5 | BR25: 6 | BS25: 7 | BT25: 8 | BU25: 9 | BV25: 10 | BW25: 11 | BX25: 12 | BY25: 13 | BZ25: 14 | CA25: 15 | CB25: 16 | CC25: 17 | CD25: 18 | CE25: 19 | CF25: 20 | CG25: 21 | CH25: 22 | CI25: 23 | CJ25: 24 | CK25: 25 | CL25: 26 | CM25: 27 | CN25: 28 | CO25: 29 | CP25: 30 | CQ25: 31
A26: a | B26: Arista 60 | D26: 400 | E26: Chimney | Y26: 150 | Z26: 50 | AS26: 150 | AT26: 50
A27: a | B27: Arista 90 | D27: 400 | E27: Chimney | Z27: 50 | AA27: 100 | AT27: 100 | AU27: 100
A28: a | B28: Asteria 60 | D28: 745 | E28: Chimney | L28: 145 | R28: 150 | S28: 150 | T28: 100 | AL28: 150 | AM28: 150 | AN28: 100
A29: a | B29: Asteria 90 | D29: 600 | E29: Chimney | T29: 50 | U29: 150 | V29: 200 | AO29: 150 | AP29: 150 | AQ29: 100
A30: a | B30: Cube 60 | D30: 19314 | E30: Chimney | G30: 150 | H30: 150 | J30: 150 | K30: 150 | L30: 150 | M30: 150 | N30: =100+314 -> 414 | AB30: 300 | AC30: 300 | AE30: =300+200 -> 500 | AF30: =300+200 -> 500 | AG30: =300+200 -> 500 | AH30: =300+200 -> 500 | AI30: =200+200 -> 400 | AV30: 300 | AW30: 300 | AX30: 300 | AZ30: =300+200 -> 500 | BA30: =300+200 -> 500 | BB30: =300+200 -> 500 | BC30: =200+200 -> 400 | BD30: 100 | BE30: 250 | BF30: 250 | BG30: =300+250 -> 550 | BH30: =300+250 -> 550 | BI30: =300+250 -> 550 | BJ30: =350+250 -> 600 | BK30: =350+250 -> 600 | BL30: =400+250 -> 650
A31: a | B31: Elara 60 | D31: 525 | E31: Chimney | Y31: 100 | Z31: 100 | AA31: 50 | AS31: 100 | AT31: 100 | AU31: 50
A32: a | B32: Elara 90 | D32: 525 | E32: Chimney | AA32: 50 | AB32: 100 | AC32: 100 | AU32: 50 | AV32: 100 | AW32: 100
A33: a | B33: Eris 60 | D33: 675 | E33: Chimney | R33: 100 | S33: 100 | AN33: 100 | AO33: 100
A34: a | B34: Eris 90 | D34: 825 | E34: Chimney | T34: 100 | U34: 100 | V34: 50 | AP34: 100 | AQ34: 150
A35: a | B35: Orion | D35: 972 | E35: Chimney | Q35: 50 | R35: 50 | S35: 50 | T35: 50 | U35: 50 | V35: 50 | X35: 24
A36: a | B36: Dorado 3B | D36: 1120 | E36: Burner | L36: 20 | X36: 150 | Y36: 150
A37: a | B37: Dorado 4B | D37: 2442 | E37: Burner | M37: 142 | Z37: 150 | AA37: 150 | AB37: 150 | AC37: 150 | AE37: 100
A38: a | B38: Dorado Premium | D38: 2075 | E38: Burner | N38: 100 | O38: 100 | Q38: 75 | AC38: 100 | AE38: 100 | AF38: 100 | AG38: 100 | AH38: 100 | AI38: 100
A39: a | B39: Solaria 3B | D39: 1325 | E39: Burner | K39: 100 | M39: 100 | Q39: 100 | T39: 100 | V39: 100 | Y39: 125 | AM39: 100 | AS39: 50 | AU39: 50 | AW39: 50 | AZ39: 50 | BB39: 50 | BD39: 50 | BG39: 50 | BI39: 50 | BK39: 50
A40: a | B40: Solaria 4B | D40: 2050 | E40: Burner | L40: 100 | N40: 100 | O40: 100 | R40: 100 | S40: 100 | U40: 100 | X40: 100 | Z40: 100 | AA40: 100 | AB40: 50 | AN40: 100 | AT40: 50 | AV40: 50 | AX40: 50 | BA40: 50 | BC40: 50 | BE40: 50 | BH40: 50 | BJ40: 50 | BL40: 50
...

Sheet S&OP
A1: Sl. No | B1: Model | C1: Category | D1: OND | E1: Oct | F1: Nov | G1: Dec | H1: 45902 | I1: 45909 | J1: =I1+7 -> 45916 | K1: =J1+7 -> 45923 | L1: 45930 | M1: 45937 | N1: 45944 | O1: 45958 | P1: =O1+7 -> 45965 | Q1: =P1+7+7 -> 45979 | R1: =Q1+7 -> 45986 | S1: =R1+7 -> 45993 | T1: =S1+7 -> 46000 | U1: =T1+8 -> 46008 | V1: =U1+6 -> 46014 | W1: =V1+7 -> 46021 | X1: =W1+20 -> 46041 | Y1: 46055 | Z1: 46062
A2: 1 | B2: Arista 60 | C2: Chimney | D2: =SUM(E2:G2) -> 0 | E2: 0 | F2: 0 | G2: 0 | H2: oct cancelled | I2: oct cancelled | J2: oct cancelled | K2: oct cancelled | L2: No OCT plan | M2: No OCT plan | N2: Discuss in NOV 1st week | O2: Anurag to share plan next week | P2: Dec -200 Finalised, COGS approval to be sent by R&D | Q2: Dec 4th week FG | R2: Jan 1st week FG | S2: Jan 1st week FG | T2: Jan 1st week FG | U2: Jan 1st week FG | V2: Jan 1st week FG | X2: Jan - 200 Pending of OND | Y2: 200 nos by 15th Feb
A3: 2 | B3: Arista 90 | C3: Chimney | D3: =SUM(E3:G3) -> 0 | E3: 0 | F3: 0 | G3: 0 | H3: oct cancelled | I3: oct cancelled | J3: oct cancelled | K3: oct cancelled | L3: No OCT plan | M3: No OCT plan | N3: Discuss in NOV 1st week | O3: Anurag to share plan next week | P3: Dec -200 Finalised, COGS approval to be sent by R&D | Q3: Dec 4th week FG | R3: Jan 1st week FG | S3: Jan 1st week FG | T3: Jan 1st week FG | U3: Jan 1st week FG | V3: Jan 1st week FG | X3: Jan - 200 Pending of OND | Y3: 200 nos by 15th Feb
A4: 3 | B4: Asteria 60 | C4: Chimney | D4: =SUM(E4:G4) -> 600 | E4: 200 | F4: 200 | G4: 200 | H4: no change in plan | I4: no change in plan | J4: no change in plan | K4: no change in plan | L4: No changes | M4: No Changes | N4: OCT 22 FG | O4: FG by 4th Nov , BLDC for Dec ( Tentative ) | P4: Oct - by 4th Nov, Nov by 18th Nov, Dec by Nov 28th , BLDC FG - 50 Pcs by 10th Dec | Q4: Dec 1st week 400 nos, Sales to give Jan nos today | R4: No Changes | S4: No Changes | T4: No Changes | U4: No Changes | V4: 24th Dec | W4: 100 Nos pending | X4: Jan - 145 Pcs Pending of OND | Y4: 0 Pending
A5: 4 | B5: Asteria 90 | C5: Chimney | D5: =SUM(E5:G5) -> 550 | E5: 200 | F5: 200 | G5: 150 | H5: no change in plan | I5: no change in plan | J5: no change in plan | K5: no change in plan | L5: No changes | M5: No Changes | N5: OCT 22 FG | O5: FG by 4th Nov , BLDC for Dec ( Tentative ) | P5: Oct - by 4th Nov, Nov by 18th Nov, Dec by Nov 28th , BLDC FG - 50 Pcs by 10th Dec | Q5: Dec 1st week 350 nos, Sales to give Jan nos today | R5: No Changes | S5: No Changes | U5: No Changes | V5: 24th Dec | W5: Produciton completed | X5: 0 Pending | Y5: 0 Pending
A6: 5 | B6: Cube | C6: Chimney | D6: =SUM(E6:G6) -> 4000 | E6: 0 | F6: =80*25 -> 2000 | G6: 2000 | H6: to be updated by 2nd eve + move 3k units from jan to dec | I6: Discussion with R&D for vaneer printing. | J6: Oct - No veneer, 300 moved to Grey | K6: no change | L6: OCT 15h 500 Nos @ 500rs extra | M6: OCT 20th to 22nd FG ready | N6: Magenta color sample to be submited to marketing. Divyanshu by 15th will sahre the box design changes. | O6: 1.Shade Card to be arranged within 3-4 days. 2.Packaging Artwork to be changed. 3. November 10th FG - 1400 (Black), 600 (Grey) 4. November 20th - 1400 (Black), 600 (Grey) | P6: No change in plan | Q6: 700Nos FG in 4th week 1300 Nos of FG in 5th week | S6: Next week 1100 with thermocol, Production to continue the Jan pro | T6: Next week 1100 with thermocol, Production to continue the Jan pro | U6: 1100 will be completed this week remaining 2000 nos will be available by Dec last week | W6: Jan 1st week 4000 nos will be completed | X6: Jan - 364 Pcs Pending of OND | Y6: 0 Pending
A7: 6 | B7: Elara 60 | C7: Chimney | D7: =SUM(E7:G7) -> 0 | E7: 0 | F7: 0 | G7: 0 | H7: oct cancelled | I7: oct cancelled | J7: oct cancelled | K7: oct cancelled | L7: No OCT plan | M7: Anurag will give plan on 15th | N7: Anurag to give plan before diwali | O7: Anurag to share plan next week | P7: December 250 is finalised , COGS approval to be sent by R&D | Q7: Dec 5th week FG | R7: No Changes | S7: No Changes | T7: Jan 1st week FG | U7: Jan 1st week FG | V7: Jan 1st week FG | X7: Jan - 250 Pending of OND | Y7: 250 nos by 15th Feb
A8: 7 | B8: Elara 90 | C8: Chimney | D8: =SUM(E8:G8) -> 0 | E8: 0 | F8: 0 | G8: 0 | H8: oct cancelled | I8: oct cancelled | J8: oct cancelled | K8: oct cancelled | L8: No OCT plan | M8: Anurag will give plan on 15th | N8: Anurag to give plan before diwali | O8: Anurag to share plan next week | P8: December 250 is finalised , COGS approval to be sent by R&D | Q8: Dec 5th week FG | R8: No Changes | S8: No Changes | T8: Jan 1st week FG | U8: Jan 1st week FG | V8: Jan 1st week FG | X8: Jan - 250 Pending of OND | Y8: 250 nos by 15th Feb
A9: 8 | B9: Eris 60 | C9: Chimney | D9: =SUM(E9:G9) -> 0 | E9: 0 | F9: 0 | G9: 0 | H9: no change in plan | I9: no change in plan | J9: no change in plan | K9: oct producttion not required | L9: No changes | M9: No Changes | N9: No changes | O9: Nov - 0, Dec - Number to be revised in next week | P9: Oct,Nov,Dec - 0 | Q9: Oct,Nov,Dec - 0 | R9: No Changes | S9: No Changes | T9: No Changes | U9: No Changes | V9: No Changes | W9: No Changes | X9: No Changes | Y9: 0 Pending
A10: 9 | B10: Eris 90 | C10: Chimney | D10: =SUM(E10:G10) -> 0 | E10: 0 | F10: 0 | G10: 0 | H10: no change in plan | I10: no change in plan | J10: no change in plan | K10: oct producttion not required | L10: No changes | M10: No Changes | N10: No changes | O10: Nov - 0, Dec - Number to be revised in next week | P10: Oct,Nov,Dec - 0 | Q10: Oct,Nov,Dec - 0 | R10: No Changes | S10: No Changes | T10: No Changes | U10: No Changes | V10: No Changes | W10: No Changes | X10: No Changes | Y10: 0 Pending
A11: 10 | B11: Orion | C11: Chimney | D11: =SUM(E11:G11) -> 324 | E11: 0 | F11: 324 | G11: 0 | H11: no change in plan | I11: no change in plan | J11: no change in plan | K11: harmeet to bill today | L11: No changes | M11: Production moved to OCT 5th week | N11: Production moved to OCT 5th week | O11: FG by 10th Nov | P11: FG by 10th Nov | Q11: No change | R11: No Changes | S11: No Changes | T11: No Changes | U11: No Changes | V11: No Changes | W11: Produciton completed | X11: Production completed | Y11: 0 Pending
A12: 11 | B12: Dorado 3B | C12: Burner | D12: =SUM(E12:G12) -> 800 | E12: 300 | F12: 300 | G12: 200 | H12: no change in plan | I12: no change in plan | J12: no change in plan | K12: no change in plan | L12: No changes | M12: No Changes | N12: No changes | O12: November 1st Week | P12: November 1st Week | Q12: Dec 2nd week | R12: No Changes | S12: No Changes | T12: No Changes | U12: No Changes | V12: No Changes | W12: Produciton completed | X12: Production completed | Y12: 0 Pending
A13: 12 | B13: Dorado 4B | C13: Burner | D13: =SUM(E13:G13) -> 1600 | E13: 600 | F13: 500 | G13: 500 | H13: no change in plan | I13: no change in plan | J13: no change in plan | K13: no change in plan | L13: No changes | M13: No Changes | N13: No changes | O13: November 1st Week | P13: November 1st Week | Q13: Dec 2nd week | R13: No Changes | S13: No Changes | T13: No Changes | U13: No Changes | V13: No Changes | W13: Produciton completed | X13: Production completed | Y13: 0 Pending
A14: 13 | B14: Altair 4B | C14: Burner | D14: 1255 | E14: 0 | F14: 700 | G14: 555 | H14: next week realistic timeline | I14: Noember 1st week FG | J14: Noember 1st week FG | K14: November 1st week FG | L14: Nov 3rd Week FG | M14: Nov 3rd Week FG | N14: Nov 3rd Week FG | O14: Nov 3rd Week FG | P14: Nov 3rd Week FG | Q14: 1400 to be ready by DEC 2nd week | R14: No Changes | S14: No Changes | T14: No Changes | U14: No Changes | V14: No Changes | W14: Produciton completed | X14: Production completed | Y14: 0 Pending
A15: 14 | B15: Solaria 3B | C15: Burner | D15: =SUM(E15:G15) -> 350 | E15: 0 | F15: 0 | G15: 350 | J15: no change in plan | K15: no change in plan | L15: No changes | M15: R&D should make one master sample | N15: R&D should make one master sample | O15: R&D should make one master sample | P15: Dec - 350 | Q15: Dec 3rd week | R15: Try to deliver in 2nd week | S15: Dec 4th week | T15: Dec 4th week | U15: Jan 1st week FG | V15: Jan 1st week FG | W15: Jan 1st week FG | X15: Jan - 350 Pending in 4th week | Y15: 262 nos by 15th Feb
A16: 15 | B16: Solaria 4B | C16: Burner | D16: =SUM(E16:G16) -> 550 | E16: 0 | F16: 0 | G16: 550 | H16: 22nd sept despatch of 130 units | I16: 22nd sept despatch of 130 units | J16: no change in plan | K16: delayed to 27th sept | L16: 120 FG ready/10-12 MSL | M16: have customer feedback by month end | N16: have customer feedback by month end | O16: Have customer feedback by month end | P16: Dec - 550 | Q16: Dec 3rd week | R16: Try to deliver in 2nd week | S16: Dec 4th week | T16: Dec 4th week | U16: Jan 1st week FG | V16: Jan 1st week FG | W16: Jan 1st week FG | X16: Jan - 425 Pending in 4th week | Y16: 374 nos by 15th Feb
A17: 16 | B17: Zyra | C17: Burner | D17: =SUM(E17:G17) -> 0 | E17: 0 | F17: 0 | G17: 0 | H17: 30th sept | I17: 22nd sept | J17: no change in plan | K17: 50 done, rest by 30gh | L17: 220 FG ready | M17: have customer feedback by month end | N17: have customer feedback by month end | O17: Order when MSL is 100 Units, R&D to provide Spares for last 290 Batch | P17: Order when MSL is 100 Units, R&D to provide Spares for last 290 Batch | Q17: Order when MSL is 100 Units, R&D to provide Spares for last 290 Batch | S17: Order when MSL is 100 Units, R&D to provide Spares for last 290 Batch | T17: Order when MSL is 100 Units, R&D to provide Spares for last 290 Batch | U17: Order when MSL is 100 Units, R&D to provide Spares for last 290 Batch | V17: Order when MSL is 100 Units, R&D to provide Spares for last 290 Batch | W17: No Changes | X17: Order when MSL is 100 Units | Y17: Order when MSL is 100 Units
A18: 17 | B18: Auriga 3B | C18: Burner | D18: =SUM(E18:G18) -> 250 | E18: 250 | F18: 0 | G18: 0 | H18: additional order 1500 unit valve only | I18: additional order 1500 unit valve only | J18: 3B- 306 | K18: 3b 250 | L18: No changes | M18: No Changes | N18: No Changes | O18: Ticket Data to be reviewed | P18: Dec - 500 Pcs Cancelled on 7th November | Q18: No change | R18: No Changes | S18: No Changes | T18: No Changes | U18: No Changes | V18: No Changes | W18: No Changes | X18: Production completed | Y18: 0 Pending
A19: 18 | B19: Auriga 4B | C19: Burner | D19: =SUM(E19:G19) -> 250 | E19: 250 | F19: 0 | G19: 0 | H19: additional order 1500 unit valve only | I19: additional order 1500 unit valve only | J19: 4B - 309 | K19: 4b 250 | L19: No changes | M19: No Changes | N19: No Changes | O19: Ticket Data to be reviewed | P19: Dec - 500 Pcs Cancelled on 7th November | Q19: No change | R19: No Changes | S19: No Changes | T19: No Changes | U19: No Changes | V19: No Changes | W19: No Changes | X19: Production completed | Y19: 0 Pending
A20: 19 | B20: Asteria 60 - BLDC | C20: Chimney | D20: =SUM(E20:G20) -> 50 | E20: 0 | F20: 0 | G20: 50 | Q20: Dec 1st week FG and before 10th Bng delivery | R20: Dec 1st week FG and before 10th Bng delivery | S20: Dec 1st week FG and before 10th Bng delivery | T20: 15th Dispatch | U20: 22nd Dispatch | W20: 6th Dispactch | X20: This week - 14 pcs pending | Y20: 14 pcs by 10th Feb
A21: 20 | B21: Asteria 90 - BLDC | C21: Chimney | D21: =SUM(E21:G21) -> 50 | E21: 0 | F21: 0 | G21: 50 | Q21: Dec 1st week FG and before 10th Bng delivery | R21: Dec 1st week FG and before 10th Bng delivery | S21: Dec 1st week FG and before 10th Bng delivery | T21: 15th Dispatch | U21: 22nd Dispatch | V21: 3rd Jan FG | W21: 6th Dispactch | X21: This week - 10 Pcs pending | Y21: 10 pcs by 10th Feb
B23: TOTAL | D23: =SUM(D2:D21) -> 10629 | E23: =SUM(E2:E21) -> 1800 | F23: =SUM(F2:F21) -> 4224 | G23: =SUM(G2:G21) -> 4605
A25: Sl. No | B25: Model | C25: Category | D25: JFM | E25: Jan | F25: Feb | G25: Mar | O25: 45958 | P25: =P1 -> 45965 | Q25: =Q1 -> 45979 | R25: =Q25+7 -> 45986 | S25: =R25+7 -> 45993 | T25: =S25+7 -> 46000 | U25: =T25+8 -> 46008 | V25: =U25+6 -> 46014 | W25: =V25+7 -> 46021
A26: 1 | B26: Arista 60 | C26: Chimney | D26: =SUM(E26:G26) -> 0 | E26: 0 | F26: 0 | G26: 0 | O26: Numbers - TBD by Anurag | P26: Feb quantity to be shared by Nov end, | Q26: NO Jan production | R26: Feb numbers updated | S26: Jan 1st week FG | T26: Jan 1st week FG | U26: Jan 2nd Week FG | V26: Jan 2nd Week FG | W26: Jan 4th Week FG | X26: Feb made Zero | Y26: No change
A27: 2 | B27: Arista 90 | C27: Chimney | D27: =SUM(E27:G27) -> 0 | E27: 0 | F27: 0 | G27: 0 | O27: Numbers - TBD by Anurag | P27: Feb quantity to be shared by Nov end, | Q27: NO Jan production | R27: Feb numbers updated | S27: Jan 1st week FG | T27: Jan 1st week FG | U27: Jan 2nd Week FG | V27: Jan 2nd Week FG | W27: Jan 4th Week FG | X27: Feb made Zero | Y27: No change
A28: 3 | B28: Asteria 60 | C28: Chimney | D28: =SUM(E28:G28) -> 400 | E28: 200 | F28: 200 | G28: 0 | O28: JAN - NO BLDC | P28: Feb quantity to be shared by Nov end, | Q28: No change | R28: Feb numbers updated | T28: Jan 3rd week FG | U28: Jan 3rd week FG | V28: Jan 3rd week FG | W28: Jan 3rd week FG | X28: Jan - Feb in Jan 5th week | Y28: 200 nos by 15th Feb
A29: 4 | B29: Asteria 90 | C29: Chimney | D29: =SUM(E29:G29) -> 200 | E29: 0 | F29: 0 | G29: 200 | O29: JAN - NO BLDC | P29: Feb quantity to be shared by Nov end, | Q29: No change | R29: Feb numbers updated | T29: Jan 3rd week FG | U29: Jan 3rd week FG | V29: Jan 3rd week FG | W29: Jan 3rd week FG | X29: Jan - Feb in Jan 5th week | Y29: 200 nos by 15th Feb
A30: 5 | B30: Cube | C30: Chimney | D30: =SUM(E30:G30) -> 18000 | E30: 3000 | F30: 6000 | G30: 9000 | O30: Jan, Feb - No Change. | P30: FG by JAN 15th | Q30: FG by JAN 15th | R30: FG by JAN 15th | T30: FG by JAN 15th | U30: FG by JAN 15th | V30: 2000 nos before Jan 15th | W30: 2000 nos before Jan 15th | X30: Jan - 2000 in Jan 5th Week | Y30: 4000 pcs in Feb
A31: 6 | B31: Elara 60 | C31: Chimney | D31: =SUM(E31:G31) -> 0 | E31: 0 | F31: 0 | G31: 0 | O31: Numbers - TBD by Anurag | P31: Feb quantity to be shared by Nov end, | Q31: NO Jan production | R31: Feb numbers updated | T31: Jan 5th Week | U31: Jan 5th Week | V31: Jan 5th Week | W31: Jan 5th Week | X31: Feb made Zero , March updated | Y31: No change
A32: 7 | B32: Elara 90 | C32: Chimney | D32: =SUM(E32:G32) -> 0 | E32: 0 | F32: 0 | G32: 0 | O32: Numbers - TBD by Anurag | P32: Feb quantity to be shared by Nov end, | Q32: NO Jan production | R32: Feb numbers updated | T32: Jan 5th Week | U32: Jan 5th Week | V32: Jan 5th Week | W32: Jan 5th Week | X32: Feb made Zero , March updated | Y32: No change
A33: 8 | B33: Eris 60 | C33: Chimney | D33: =SUM(E33:G33) -> 200 | E33: 0 | F33: 0 | G33: 200 | O33: Numbers - TBD by Anurag | P33: Feb quantity to be shared by Nov end, | Q33: No change | R33: Feb numbers updated | T33: Jan 1st week FG | U33: Jan 2nd Week FG | V33: Jan 2nd Week FG | W33: Jan 2nd Week FG | X33: Jan - 5th Week , March updated | Y33: Jan, Feb - 15th Feb
A34: 9 | B34: Eris 90 | C34: Chimney | D34: =SUM(E34:G34) -> 200 | E34: 0 | F34: 0 | G34: 200 | O34: Numbers - TBD by Anurag | P34: Feb quantity to be shared by Nov end, | Q34: No change | R34: Feb numbers updated | T34: Jan 1st week FG | U34: Jan 2nd Week FG | V34: Jan 2nd Week FG | W34: Jan 2nd Week FG | X34: Jan - 5th Week , March updated | Y34: Jan, Feb - 18th Feb
A35: 10 | B35: Orion | C35: Chimney | D35: =SUM(E35:G35) -> 648 | E35: 324 | F35: 120 | G35: 204 | O35: No Change in plan | P35: No change in plan | Q35: No change | R35: No Changes | T35: No Changes | U35: Jan 2nd Week FG | V35: Jan 1st week FG | W35: Jan 1st week FG | X35: Jan - 4th Week | Y35: Jan 88 pcs pending - 7th Feb
A36: 11 | B36: Dorado 3B | C36: Burner | D36: =SUM(E36:G36) -> 1100 | E36: 300 | F36: 400 | G36: 400 | O36: No Change in plan | P36: No change in plan | Q36: No change | R36: No Changes | T36: No Changes | U36: Jan 2nd Week FG | V36: Jan 2nd Week FG | W36: Jan 2nd Week FG | X36: Jan - 5th Week , Feb - Feb 4th Week on wards | Y36: 149 pcs pending by 14th Feb | AA36: Till Dec | AB36: Jan | AC36: Feb | AD36: Mar
A37: 12 | B37: Dorado 4B | C37: Burner | D37: =SUM(E37:G37) -> 2300 | E37: 700 | F37: 800 | G37: 800 | O37: No Change in plan | P37: No change in plan | Q37: No change | R37: No Changes | T37: No Changes | U37: Jan 2nd Week FG | V37: Jan 2nd Week FG | W37: Jan 2nd Week FG | X37: Jan - 5th Week , Feb - Feb 4th Week on wards | Y37: 520 pcs pending by 14th Feb | AA37: 2500 | AB37: 5000 | AC37: 7000 | AD37: 9000
A38: 13 | B38: Altair 4B | C38: Burner | D38: =SUM(E38:G38) -> 0 | E38: 0 | F38: 0 | G38: 0 | O38: Jan - Feb - Mar - Old Altair | P38: No change in plan | Q38: No change | R38: No Changes | T38: No Changes | U38: Jan 5th Week FG | V38: Jan 5th Week FG | W38: Jan 5th Week FG | X38: Jan - Feb - in Feb 3rd Week | Y38: Feb 600pcs by 4th week
A39: 14 | B39: Solaria 3B | C39: Burner | D39: =SUM(E39:G39) -> 1075 | E39: 275 | F39: 350 | G39: 450 | O39: Wait for Feedback | P39: Jan - 275 | Q39: No change | R39: No Changes | T39: No Changes | U39: Jan 3rd Week FG | V39: Jan 3rd Week FG | W39: Jan 3rd Week FG | X39: Jan - Feb 1st Week , Feb - 3rd Week | Y39: Jan - Feb 4th Week
A40: 15 | B40: Solaria 4B | C40: Burner | D40: =SUM(E40:G40) -> 950 | E40: 400 | F40: 550 | G40: 0 | O40: Wait for Feedback | P40: Jan - 400 | Q40: No change | R40: No Changes | T40: No Changes | U40: Jan 3rd Week FG | V40: Jan 3rd Week FG | W40: Jan 3rd Week FG | X40: Jan - Feb 1st Week , Feb - 3rd Week | Y40: Jan - Feb 4th Week
A41: 16 | B41: Zyra | C41: Burner | D41: =SUM(E41:G41) -> 0 | E41: 0 | F41: 0 | G41: 0 | O41: Wait for MSL 100 | P41: March 290 nos | Q41: March 290 nos | R41: No Changes | T41: No Changes | U41: No Changes | V41: No Changes | W41: No Changes | X41: Order when MSL is 100 Units | Y41: Order when MSL is 100 Units
A42: 17 | B42: Auriga 3B | C42: Burner | D42: =SUM(E42:G42) -> 1500 | E42: 450 | F42: 450 | G42: 600 | O42: Ticket Data to be reviewed | P42: Feb quantity to be shared by Nov end, | Q42: Try to deliver before last week of Dec | R42: Anurag to update the quantity by next week | T42: Quantiy for feb is 0 | U42: Jan 18th FG | V42: Jan 18th FG | W42: Jan 18th FG | X42: March - 0 , But plan for 1500 | Y42: Jan - Feb 4th week
...

Sheet Closed WO
A1: BN-SO-2526-0021 | B1: Eris 60cm | D1: Chimney | E1: JAS | F1: =210+600-110 -> 700 | G1: 700 | H1: =F1-G1 -> 0
A2: BN-SO-2526-0011 | B2: Elara 60cm | D2: Chimney | E2: JAS | F2: 493 | G2: 493 | H2: =F2-G2 -> 0
A3: BN-SO-2526-0021 | B3: Eris 90cm | D3: Chimney | E3: JAS | F3: 600 | G3: 600 | H3: =F3-G3 -> 0
A4: BN-SO-2526-0009 | B4: Cube 60 W/O- Wave - Black | D4: Chimney | E4: JAS | F4: 1692 | G4: 1692 | H4: =F4-G4 -> 0
A5: BN-SO-2526-0027 | B5: Auriga 3B | C5: 60 | D5: Burner | E5: OND | F5: 250 | G5: 250 | H5: =F5-G5 -> 0 | I5: 45859 | J5: 45869 | K5: BN-SO-2526-0027 | L5: 45870 | M5: 45901 | P5: =M5+C5+15 -> 45976 | Q5: =P5+10 -> 45986 | R5: =Q5+7 -> 45993 | S5: =R5+1 -> 45994 | T5: =S5-I5-1 -> 134 | U5: Costing to be finalised
A6: BN-SO-2526-0027 | B6: Auriga 4B | C6: 60 | D6: Burner | E6: OND | F6: 250 | G6: 250 | H6: =F6-G6 -> 0 | I6: 45859 | J6: 45869 | K6: BN-SO-2526-0027 | L6: 45870 | M6: 45901 | P6: =M6+C6+15 -> 45976 | Q6: =P6+10 -> 45986 | R6: =Q6+7 -> 45993 | S6: =R6+1 -> 45994 | T6: =S6-I6-1 -> 134 | U6: Costing to be finalised

Sheet internal to sales
D4: Offline_Sku Plan | P4: Model | Q4: Type | R4: July Req | S4: to give | T4: Aug Req | U4: to give
C5: 18th July'25 | P5: Asteria | Q5: 60 CM | R5: 30 | S5: 30 | T5: 30
C6: Model | D6: July | E6: to be given | F6: August | G6: to be given | H6: Sept | I6: to be given | J6: Oct | K6: Nov | L6: Dec | P6: Asteria | Q6: 90 CM | R6: 30 | S6: 30 | T6: 30
